<?xml version="1.0"?>
<robot name="arm_robot">
  <material name="red">
    <color rgba="1.0 0.0 0.0 2.0"/>
  </material>
  <material name="blue">
    <color rgba="0.0 0.0 1.0 2.0"/>
  </material>
  <material name="green">
    <color rgba="0.0 1.0 0.0 2.0"/>
  </material>
  <material name="white">
    <color rgba="1.0 1.0 1.0 2.0"/>
  </material>

  <link name="base_link"/>

  <joint name="body1_joint" type="revolute">
    <parent link="base_link"/>
    <child  link="body1_link"/>
    <origin xyz="0 0 0" rpy="0 0 0"/>
    <limit lower="-1.5" upper="1.5" effort="0" velocity="0"/>
    <axis xyz="0 0 1"/>
  </joint>
  <link name="body1_link">
    <visual>
      <geometry>
        <cylinder length="0.2" radius="0.2"/>
      </geometry>
      <origin xyz="0 0 0.1" rpy="0.0 0.0 0.0"/>
      <material name="red"/>
    </visual>
  </link>

  <!--========================================================================-->

  <joint name="body2_joint" type="revolute">
    <parent link="body1_link"/>
    <child  link="body2_link"/>
    <origin xyz="0 0 0.2" rpy="0 0 0"/>
    <limit lower="-1.5" upper="1.5" effort="0" velocity="0"/>
  </joint>
  <link name="body2_link">
    <visual>
      <geometry>
        <box size="0.1 0.1 0.4"/>
      </geometry>
      <origin xyz="0 0 0.2" rpy="0 0 0"/>
      <material name="white"/>
    </visual>
  </link>

  <!--========================================================================-->

  <joint name="body3_joint" type="revolute">
    <parent link="body2_link"/>
    <child  link="body3_link"/>
    <origin xyz="0 0 0.4" rpy="0 0 0"/>
    <limit lower="-1.5" upper="1.5" effort="0" velocity="0"/>
  </joint>
  <link name="body3_link">
    <visual>
      <geometry>
        <box size="0.1 0.1 0.4"/>
      </geometry>
      <origin xyz="0 0 0.2" rpy="0 0 0"/>
      <material name="red"/>
    </visual>
  </link>

  <!--========================================================================-->

  <joint name="body4_joint" type="revolute">
    <parent link="body3_link"/>
    <child  link="body4_link"/>
    <origin xyz="0 0 0.4" rpy="0 0 0"/> <limit lower="-1.5" upper="1.5" effort="0" velocity="0"/>
  </joint>
  <link name="body4_link">
    <visual>
      <geometry>
        <box size="0.1 0.1 0.2"/>
      </geometry>
      <origin xyz="0 0 0.1" rpy="0 0 0"/>
      <material name="white"/>
    </visual>
  </link>


  <!--========================================================================-->

  <joint name="hand_joint" type="fixed">
    <parent link="body4_link"/>
    <child  link="link"/>
    <origin xyz="0 0 0.2" rpy="0 0 0"/>
    <limit lower="-1.5" upper="1.5" effort="0" velocity="0"/>
    <axis xyz="0 0 1" />
  </joint>
  <link name="link">
    <visual>
      <geometry>
        <!--box size="0.1 0.1 0.2"/-->
        <cylinder length="0.1" radius="0.02"/>
      </geometry>
      <origin xyz="0 0 0.05" rpy="0 0 0"/>
      <material name="red"/>
    </visual>
  </link>


  <!--========================================================================-->

  <joint name="hands_joint" type="fixed">
    <parent link="link"/>
    <child  link="hand"/>
    <origin xyz="0 0 0.1" rpy="0 0 0"/>
    <limit lower="-1.5" upper="1.5" effort="0" velocity="0"/>
    <axis xyz="0 0 1" />
  </joint>
  <link name="hand">
    <visual>
      <geometry>
        <!--box size="0.1 0.1 0.2"/-->
        <cylinder length="0.05" radius="0.05"/>
      </geometry>
      <origin xyz="0 0 0.025" rpy="0 0 0"/>
      <material name="white"/>
    </visual>
  </link>

  <!--========================================================================-->

  <joint name="hand1_joint" type="revolute">
    <parent link="hand"/>
    <child  link="hand1"/>
    <origin xyz="0.03 0 0.05" rpy="0 0 0"/>
    <limit lower="-0.1" upper="0.349" effort="0" velocity="0"/>
    <axis xyz="0 1 0" />
  </joint>
  <link name="hand1">
    <visual>
      <geometry>
        <box size="0.02 0.02 0.05"/>
      </geometry>
      <origin xyz="0 0 0.025" rpy="0 0 0"/>
      <material name="red"/>
    </visual>
  </link>


  <!--========================================================================-->

  <joint name="hand11_joint" type="fixed">
    <parent link="hand1"/>
    <child  link="hand11"/>
    <origin xyz="0.0 0 0.05" rpy="0 -0.174 0"/>
  </joint>
  <link name="hand11">
    <visual>
      <geometry>
        <box size="0.02 0.02 0.05"/>
      </geometry>
      <origin xyz="0 0 0.025" rpy="0 0 0"/>
      <material name="red"/>
    </visual>
  </link>


  <!--========================================================================-->

  <joint name="hand2_joint" type="revolute">
    <parent link="hand"/>
    <child  link="hand2"/>
    <origin xyz="-0.03 0.0 0.05" rpy="0 0 0"/>
    <limit lower="-0.349" upper="0.1" effort="0" velocity="0"/>
    <axis xyz="0 1 0" />
  </joint>
  <link name="hand2">
    <visual>
      <geometry>
        <box size="0.02 0.02 0.05"/>
      </geometry>
      <origin xyz="0 0 0.025" rpy="0 0 0"/>
      <material name="red"/>
    </visual>
  </link>

  <!--========================================================================-->

  <joint name="hand22_joint" type="fixed">
    <parent link="hand2"/>
    <child  link="hand22"/>
    <origin xyz="0.0 0 0.05" rpy="0 0.174 0"/>
  </joint>
  <link name="hand22">
    <visual>
      <geometry>
        <box size="0.02 0.02 0.05"/>
      </geometry>
      <origin xyz="0 0 0.025" rpy="0 0 0"/>
      <material name="red"/>
    </visual>
  </link>


</robot>
